<?xml version="1.0" ?>
<!-- =================================================================================== -->
<!-- |    This document was autogenerated by xacro from pioneer3at.xacro               | -->
<!-- |    EDITING THIS FILE BY HAND IS NOT RECOMMENDED                                 | -->
<!-- =================================================================================== -->
<!-- Please note that this URDF will _not_ load in gazebo -->
<robot name="pioneer3at" xmlns:controller="http://playerstage.sourceforge.net/gazebo/xmlschema/#controller" xmlns:interface="http://playerstage.sourceforge.net/gazebo/xmlschema/#interface" xmlns:sensor="http://playerstage.sourceforge.net/gazebo/xmlschema/#sensor" xmlns:xacro="http://ros.org/wiki/xacro">
  <!-- Import all Gazebo-customization elements, including Gazebo colors -->
  <gazebo reference="Pioneer3AT/base_link">
    <material>Gazebo/Red</material>
    <selfCollide>False</selfCollide>
  </gazebo>
  <gazebo reference="top_plat">
    <material>Gazebo/Black</material>
    <selfCollide>False</selfCollide>
  </gazebo>
  <gazebo reference="front_left_axle">
    <material>Gazebo/Grey</material>
    <selfCollide>False</selfCollide>
  </gazebo>
  <gazebo reference="rear_left_axle">
    <material>Gazebo/Grey</material>
    <selfCollide>False</selfCollide>
  </gazebo>
  <gazebo reference="front_right_axle">
    <material>Gazebo/Grey</material>
    <selfCollide>False</selfCollide>
  </gazebo>
  <gazebo reference="rear_right_axle">
    <material>Gazebo/Grey</material>
    <selfCollide>False</selfCollide>
  </gazebo>
  <gazebo reference="front_left_wheel">
    <material>Gazebo/Black</material>
    <selfCollide>False</selfCollide>
  </gazebo>
  <gazebo reference="rear_left_wheel">
    <material>Gazebo/Black</material>
    <selfCollide>False</selfCollide>
  </gazebo>
  <gazebo reference="front_right_wheel">
    <material>Gazebo/Black</material>
    <selfCollide>False</selfCollide>
  </gazebo>
  <gazebo reference="rear_right_wheel">
    <material>Gazebo/Black</material>
    <selfCollide>False</selfCollide>
  </gazebo>
  <gazebo reference="front_left_hub">
    <material>Gazebo/Yellow</material>
    <selfCollide>False</selfCollide>
  </gazebo>
  <gazebo reference="rear_left_hub">
    <material>Gazebo/Yellow</material>
    <selfCollide>False</selfCollide>
  </gazebo>
  <gazebo reference="front_right_hub">
    <material>Gazebo/Yellow</material>
    <selfCollide>False</selfCollide>
  </gazebo>
  <gazebo reference="rear_right_hub">
    <material>Gazebo/Yellow</material>
    <selfCollide>False</selfCollide>
  </gazebo>
  <gazebo reference="front_sonar">
    <material>Gazebo/Yellow</material>
    <selfCollide>False</selfCollide>
  </gazebo>
  <gazebo reference="rear_sonar">
    <material>Gazebo/Yellow</material>
    <selfCollide>False</selfCollide>
  </gazebo>
  <gazebo reference="right_front_wheel">
    <mu>1.000000</mu>
    <mu2>1.000000</mu2>
    <slip1>0.500000</slip1>
    <slip2>0.000000</slip2>
  </gazebo>
  <gazebo reference="left_front_wheel">
    <mu>1.000000</mu>
    <mu2>1.000000</mu2>
    <slip1>0.500000</slip1>
    <slip2>0.000000</slip2>
  </gazebo>
  <gazebo reference="right_rear_wheel">
    <mu>1.000000</mu>
    <mu2>1.000000</mu2>
    <slip1>0.500000</slip1>
    <slip2>0.000000</slip2>
  </gazebo>
  <gazebo reference="left_rear_wheel">
    <mu>1.000000</mu>
    <mu2>1.000000</mu2>
    <slip1>0.500000</slip1>
    <slip2>0.000000</slip2>
  </gazebo>
  <gazebo reference="hokuyo_link">
    <sensor name="head_hokuyo_sensor" type="gpu_ray">
      <pose>0 0 0 0 0 0</pose>
      <visualize>false</visualize>
      <update_rate>40</update_rate>
      <ray>
        <scan>
          <horizontal>
            <samples>720</samples>
            <resolution>1</resolution>
            <min_angle>-1.570796</min_angle>
            <max_angle>1.570796</max_angle>
          </horizontal>
        </scan>
        <range>
          <min>0.10</min>
          <max>30.0</max>
          <resolution>0.01</resolution>
        </range>
        <noise>
          <type>gaussian</type>
          <!-- Noise parameters based on published spec for Hokuyo laser
               achieving "+-30mm" accuracy at range < 10m.  A mean of 0.0m and
               stddev of 0.01m will put 99.7% of samples within 0.03m of the true
               reading. -->
          <mean>0.0</mean>
          <stddev>0.01</stddev>
        </noise>
      </ray>
      <plugin filename="libgazebo_ros_gpu_laser.so" name="gazebo_ros_head_hokuyo_controller">
        <topicName>/Pioneer3AT/laser/scan</topicName>
        <frameName>hokuyo_link</frameName>
      </plugin>
    </sensor>
  </gazebo>
  <!-- Import Rviz colors -->
  <material name="ChassisRed">
    <color rgba="0.851 0.0 0.0 1.0"/>
  </material>
  <material name="TopBlack">
    <color rgba="0.038 0.038 0.038 1.0"/>
  </material>
  <material name="AxleGrey">
    <color rgba="0.5 0.5 0.5 1"/>
  </material>
  <material name="SonarGold">
    <color rgba="0.9 0.6 0.2 1"/>
  </material>
  <material name="SonarYellow">
    <color rgba="0.715 0.583 0.210 1.0"/>
  </material>
  <material name="WheelBlack">
    <color rgba="0.117 0.117 0.117 1"/>
  </material>
  <material name="HubcapYellow">
    <color rgba="1.0 0.811 0.151 1.0"/>
  </material>
  <!-- Chassis -->
  <link name="Pioneer3AT/base_link">
    <visual>
      <origin rpy="0 0 0" xyz="0 0 0.177"/>
      <geometry>
        <mesh filename="package://pioneer3at_description/meshes/chassis.stl"/>
      </geometry>
      <material name="ChassisRed"/>
    </visual>
    <origin rpy="0 0 0" xyz="0 0 0.177"/>
    <mass value="14.0"/>
    <inertia ixx="1/12 * 14.0 * (0.28 + 0.25)" ixy="0.0" ixz="0.0" iyy="1/12 * 14.0 * (0.28 + 0.49)" iyz="0.0" izz="1/12 * 14.0 * (0.49 + 0.25)"/>
    <collision>
      <origin rpy="0 0 0" xyz="0 0 0.177"/>
      <geometry>
        <box size="0.49 0.28 0.25"/>
      </geometry>
    </collision>
  </link>
  <!-- Top -->
  <link name="top_plate">
    <visual>
      <origin rpy="0 0 0" xyz="0 0 0"/>
      <geometry>
        <mesh filename="package://pioneer3at_description/meshes/top.stl"/>
      </geometry>
      <material name="TopBlack"/>
    </visual>
    <inertial>
      <origin rpy="0 0 0" xyz="0 0 0"/>
      <mass value="0.1"/>
      <inertia ixx="1e-3" ixy="0.0" ixz="0.0" iyy="1e-3" iyz="0.0" izz="1e-3"/>
    </inertial>
    <collision>
      <origin rpy="0 0 0" xyz="0 0 0"/>
      <geometry>
        <mesh filename="package://pioneer3at_description/meshes/top.stl"/>
      </geometry>
    </collision>
  </link>
  <joint name="base_top_joint" type="fixed">
    <origin rpy="0 0 0" xyz="0.003 0 0.274"/>
    <parent link="Pioneer3AT/base_link"/>
    <child link="top_plate"/>
  </joint>
  <!-- Axle~Hub~Wheel  -->
  <link name="front_left_axle">
    <visual>
      <origin rpy="0 0 0" xyz="0 0 0"/>
      <geometry>
        <mesh filename="package://pioneer3at_description/meshes/axle.stl"/>
      </geometry>
      <material name="AxleGrey"/>
    </visual>
    <inertial>
      <origin rpy="0 0 0" xyz="0 0 0"/>
      <mass value="0.1"/>
      <inertia ixx="1e-3" ixy="0.0" ixz="0.0" iyy="1e-3" iyz="0.0" izz="1e-3"/>
    </inertial>
    <collision>
      <origin rpy="0 0 0" xyz="0 0 0"/>
      <geometry>
        <mesh filename="package://pioneer3at_description/meshes/axle.stl"/>
      </geometry>
    </collision>
  </link>
  <joint name="front_left_axle_joint" type="continuous">
    <origin rpy="0 0 0" xyz="0.135 0.156 0.111"/>
    <parent link="Pioneer3AT/base_link"/>
    <child link="front_left_axle"/>
    <axis xyz="0 1 0"/>
  </joint>
  <link name="front_left_hub">
    <visual>
      <origin rpy="0.0 0 0" xyz="0 0 0"/>
      <geometry>
        <mesh filename="package://pioneer3at_description/meshes/hub.stl"/>
      </geometry>
      <material name="HubcapYellow"/>
    </visual>
    <inertial>
      <origin rpy="0 0 0" xyz="0 0 0"/>
      <mass value="0.1"/>
      <inertia ixx="1e-6" ixy="0.0" ixz="0.0" iyy="1e-6" iyz="0.0" izz="1e-6"/>
    </inertial>
    <collision>
      <origin rpy="0 0 0" xyz="0 0 0"/>
      <geometry>
        <mesh filename="package://pioneer3at_description/meshes/hub.stl"/>
      </geometry>
    </collision>
  </link>
  <joint name="front_left_hub_joint" type="fixed">
    <origin rpy="0 0 0" xyz="0 0.041 0"/>
    <parent link="front_left_axle"/>
    <child link="front_left_hub"/>
  </joint>
  <link name="front_left_wheel">
    <visual>
      <origin rpy="0 0 0" xyz="0 0 0"/>
      <geometry>
        <mesh filename="package://pioneer3at_description/meshes/wheel.stl"/>
      </geometry>
      <material name="WheelBlack"/>
    </visual>
    <inertial>
      <origin rpy="0 0 0" xyz="0.125 0.201 -0.060000"/>
      <mass value="1.0"/>
      <inertia ixx="1e-6" ixy="0" ixz="0" iyy="1e-6" iyz="0" izz="1e-6"/>
    </inertial>
    <collision>
      <origin rpy="0 0 0" xyz="0 0 0"/>
      <geometry>
        <mesh filename="package://pioneer3at_description/meshes/wheel.stl"/>
      </geometry>
    </collision>
  </link>
  <joint name="front_left_wheel_joint" type="fixed">
    <origin rpy="0 0 0" xyz="0 0 0"/>
    <parent link="front_left_hub"/>
    <child link="front_left_wheel"/>
  </joint>
  <link name="front_right_axle">
    <visual>
      <origin rpy="0 0 0" xyz="0 0 0"/>
      <geometry>
        <mesh filename="package://pioneer3at_description/meshes/axle.stl"/>
      </geometry>
      <material name="AxleGrey"/>
    </visual>
    <inertial>
      <origin rpy="0 0 0" xyz="0 0 0"/>
      <mass value="0.1"/>
      <inertia ixx="1e-3" ixy="0.0" ixz="0.0" iyy="1e-3" iyz="0.0" izz="1e-3"/>
    </inertial>
    <collision>
      <origin rpy="0 0 0" xyz="0 0 0"/>
      <geometry>
        <mesh filename="package://pioneer3at_description/meshes/axle.stl"/>
      </geometry>
    </collision>
  </link>
  <joint name="front_right_axle_joint" type="continuous">
    <origin rpy="0 0 0" xyz="0.135 -0.156 0.111"/>
    <parent link="Pioneer3AT/base_link"/>
    <child link="front_right_axle"/>
    <axis xyz="0 1 0"/>
  </joint>
  <link name="front_right_hub">
    <visual>
      <origin rpy="-3.14 0 0" xyz="0 0 0"/>
      <geometry>
        <mesh filename="package://pioneer3at_description/meshes/hub.stl"/>
      </geometry>
      <material name="HubcapYellow"/>
    </visual>
    <inertial>
      <origin rpy="0 0 0" xyz="0 0 0"/>
      <mass value="0.1"/>
      <inertia ixx="1e-6" ixy="0.0" ixz="0.0" iyy="1e-6" iyz="0.0" izz="1e-6"/>
    </inertial>
    <collision>
      <origin rpy="0 0 0" xyz="0 0 0"/>
      <geometry>
        <mesh filename="package://pioneer3at_description/meshes/hub.stl"/>
      </geometry>
    </collision>
  </link>
  <joint name="front_right_hub_joint" type="fixed">
    <origin rpy="0 0 0" xyz="0 -0.041 0"/>
    <parent link="front_right_axle"/>
    <child link="front_right_hub"/>
  </joint>
  <link name="front_right_wheel">
    <visual>
      <origin rpy="0 0 0" xyz="0 0 0"/>
      <geometry>
        <mesh filename="package://pioneer3at_description/meshes/wheel.stl"/>
      </geometry>
      <material name="WheelBlack"/>
    </visual>
    <inertial>
      <origin rpy="0 0 0" xyz="0.125 -0.201 -0.060000"/>
      <mass value="1.0"/>
      <inertia ixx="1e-6" ixy="0" ixz="0" iyy="1e-6" iyz="0" izz="1e-6"/>
    </inertial>
    <collision>
      <origin rpy="0 0 0" xyz="0 0 0"/>
      <geometry>
        <mesh filename="package://pioneer3at_description/meshes/wheel.stl"/>
      </geometry>
    </collision>
  </link>
  <joint name="front_right_wheel_joint" type="fixed">
    <origin rpy="0 0 0" xyz="0 0 0"/>
    <parent link="front_right_hub"/>
    <child link="front_right_wheel"/>
  </joint>
  <link name="rear_left_axle">
    <visual>
      <origin rpy="0 0 0" xyz="0 0 0"/>
      <geometry>
        <mesh filename="package://pioneer3at_description/meshes/axle.stl"/>
      </geometry>
      <material name="AxleGrey"/>
    </visual>
    <inertial>
      <origin rpy="0 0 0" xyz="0 0 0"/>
      <mass value="0.1"/>
      <inertia ixx="1e-3" ixy="0.0" ixz="0.0" iyy="1e-3" iyz="0.0" izz="1e-3"/>
    </inertial>
    <collision>
      <origin rpy="0 0 0" xyz="0 0 0"/>
      <geometry>
        <mesh filename="package://pioneer3at_description/meshes/axle.stl"/>
      </geometry>
    </collision>
  </link>
  <joint name="rear_left_axle_joint" type="continuous">
    <origin rpy="0 0 0" xyz="-0.135 0.156 0.111"/>
    <parent link="Pioneer3AT/base_link"/>
    <child link="rear_left_axle"/>
    <axis xyz="0 1 0"/>
  </joint>
  <link name="rear_left_hub">
    <visual>
      <origin rpy="0.0 0 0" xyz="0 0 0"/>
      <geometry>
        <mesh filename="package://pioneer3at_description/meshes/hub.stl"/>
      </geometry>
      <material name="HubcapYellow"/>
    </visual>
    <inertial>
      <origin rpy="0 0 0" xyz="0 0 0"/>
      <mass value="0.1"/>
      <inertia ixx="1e-6" ixy="0.0" ixz="0.0" iyy="1e-6" iyz="0.0" izz="1e-6"/>
    </inertial>
    <collision>
      <origin rpy="0 0 0" xyz="0 0 0"/>
      <geometry>
        <mesh filename="package://pioneer3at_description/meshes/hub.stl"/>
      </geometry>
    </collision>
  </link>
  <joint name="rear_left_hub_joint" type="fixed">
    <origin rpy="0 0 0" xyz="0 0.041 0"/>
    <parent link="rear_left_axle"/>
    <child link="rear_left_hub"/>
  </joint>
  <link name="rear_left_wheel">
    <visual>
      <origin rpy="0 0 0" xyz="0 0 0"/>
      <geometry>
        <mesh filename="package://pioneer3at_description/meshes/wheel.stl"/>
      </geometry>
      <material name="WheelBlack"/>
    </visual>
    <inertial>
      <origin rpy="0 0 0" xyz="-0.125 0.201 -0.060000"/>
      <mass value="1.0"/>
      <inertia ixx="1e-6" ixy="0" ixz="0" iyy="1e-6" iyz="0" izz="1e-6"/>
    </inertial>
    <collision>
      <origin rpy="0 0 0" xyz="0 0 0"/>
      <geometry>
        <mesh filename="package://pioneer3at_description/meshes/wheel.stl"/>
      </geometry>
    </collision>
  </link>
  <joint name="rear_left_wheel_joint" type="fixed">
    <origin rpy="0 0 0" xyz="0 0 0"/>
    <parent link="rear_left_hub"/>
    <child link="rear_left_wheel"/>
  </joint>
  <link name="rear_right_axle">
    <visual>
      <origin rpy="0 0 0" xyz="0 0 0"/>
      <geometry>
        <mesh filename="package://pioneer3at_description/meshes/axle.stl"/>
      </geometry>
      <material name="AxleGrey"/>
    </visual>
    <inertial>
      <origin rpy="0 0 0" xyz="0 0 0"/>
      <mass value="0.1"/>
      <inertia ixx="1e-3" ixy="0.0" ixz="0.0" iyy="1e-3" iyz="0.0" izz="1e-3"/>
    </inertial>
    <collision>
      <origin rpy="0 0 0" xyz="0 0 0"/>
      <geometry>
        <mesh filename="package://pioneer3at_description/meshes/axle.stl"/>
      </geometry>
    </collision>
  </link>
  <joint name="rear_right_axle_joint" type="continuous">
    <origin rpy="0 0 0" xyz="-0.135 -0.156 0.111"/>
    <parent link="Pioneer3AT/base_link"/>
    <child link="rear_right_axle"/>
    <axis xyz="0 1 0"/>
  </joint>
  <link name="rear_right_hub">
    <visual>
      <origin rpy="-3.14 0 0" xyz="0 0 0"/>
      <geometry>
        <mesh filename="package://pioneer3at_description/meshes/hub.stl"/>
      </geometry>
      <material name="HubcapYellow"/>
    </visual>
    <inertial>
      <origin rpy="0 0 0" xyz="0 0 0"/>
      <mass value="0.1"/>
      <inertia ixx="1e-6" ixy="0.0" ixz="0.0" iyy="1e-6" iyz="0.0" izz="1e-6"/>
    </inertial>
    <collision>
      <origin rpy="0 0 0" xyz="0 0 0"/>
      <geometry>
        <mesh filename="package://pioneer3at_description/meshes/hub.stl"/>
      </geometry>
    </collision>
  </link>
  <joint name="rear_right_hub_joint" type="fixed">
    <origin rpy="0 0 0" xyz="0 -0.041 0"/>
    <parent link="rear_right_axle"/>
    <child link="rear_right_hub"/>
  </joint>
  <link name="rear_right_wheel">
    <visual>
      <origin rpy="0 0 0" xyz="0 0 0"/>
      <geometry>
        <mesh filename="package://pioneer3at_description/meshes/wheel.stl"/>
      </geometry>
      <material name="WheelBlack"/>
    </visual>
    <inertial>
      <origin rpy="0 0 0" xyz="-0.125 -0.201 -0.060000"/>
      <mass value="1.0"/>
      <inertia ixx="1e-6" ixy="0" ixz="0" iyy="1e-6" iyz="0" izz="1e-6"/>
    </inertial>
    <collision>
      <origin rpy="0 0 0" xyz="0 0 0"/>
      <geometry>
        <mesh filename="package://pioneer3at_description/meshes/wheel.stl"/>
      </geometry>
    </collision>
  </link>
  <joint name="rear_right_wheel_joint" type="fixed">
    <origin rpy="0 0 0" xyz="0 0 0"/>
    <parent link="rear_right_hub"/>
    <child link="rear_right_wheel"/>
  </joint>
  <!-- Sonar -->
  <!-- Front Sonar -->
  <link name="front_sonar">
    <visual>
      <origin rpy="0 0 0" xyz="0 0 0"/>
      <geometry>
        <mesh filename="package://pioneer3at_description/meshes/front_sonar.stl"/>
      </geometry>
      <material name="SonarYellow"/>
    </visual>
    <inertial>
      <origin rpy="0 0 0" xyz="0 0 0"/>
      <mass value="0.1"/>
      <inertia ixx="1e-3" ixy="0.0" ixz="0.0" iyy="1e-3" iyz="0.0" izz="1e-3"/>
    </inertial>
    <collision>
      <origin rpy="0 0 0" xyz="0 0 0"/>
      <geometry>
        <mesh filename="package://pioneer3at_description/meshes/front_sonar.stl"/>
      </geometry>
    </collision>
  </link>
  <joint name="front_sonar_joint" type="fixed">
    <origin rpy="0 0 0" xyz="0.193 0 0.25"/>
    <parent link="Pioneer3AT/base_link"/>
    <child link="front_sonar"/>
  </joint>
  <!-- Rear Sonar -->
  <link name="rear_sonar">
    <visual>
      <origin rpy="0 0 0" xyz="0 0 0"/>
      <geometry>
        <mesh filename="package://pioneer3at_description/meshes/back_sonar.stl"/>
      </geometry>
      <material name="SonarYellow"/>
    </visual>
  </link>
  <joint name="rear_sonar_joint" type="fixed">
    <origin rpy="0 0 0" xyz="-0.187 0 0.247"/>
    <parent link="Pioneer3AT/base_link"/>
    <child link="rear_sonar"/>
  </joint>
  <joint name="hokuyo_joint" type="fixed">
    <axis xyz="0 1 0"/>
    <origin rpy="0 0 0" xyz="0.2 0 0.035"/>
    <parent link="top_plate"/>
    <child link="hokuyo_link"/>
  </joint>
  <link name="hokuyo_link">
    <collision>
      <origin rpy="0 0 0" xyz="0 0 0"/>
      <geometry>
        <box size="0.1 0.1 0.1"/>
      </geometry>
    </collision>
    <visual>
      <origin rpy="0 0 0" xyz="0 0 0"/>
      <geometry>
        <mesh filename="package://pioneer3at_description/meshes/hokuyo.dae"/>
      </geometry>
    </visual>
    <inertial>
      <mass value="1e-5"/>
      <origin rpy="0 0 0" xyz="0 0 0"/>
      <inertia ixx="1e-6" ixy="0" ixz="0" iyy="1e-6" iyz="0" izz="1e-6"/>
    </inertial>
  </link>
  <!-- Sonar offsets came from p2os_driver robot_params.cc -->
  <!-- Not used, a lot of TF clutter
  <xacro:Sonar id="1"  px="0.145"  py="0.13"   rz="1.5705"/>
  <xacro:Sonar id="2"  px="0.185"  py="0.115"  rz="0.8725"/>
  <xacro:Sonar id="3"  px="0.22"   py="0.08"   rz="0.5235"/>
  <xacro:Sonar id="4"  px="0.24"   py="0.025"  rz="0.1745"/>
  <xacro:Sonar id="5"  px="0.24"   py="-0.025" rz="-0.1745"/>
  <xacro:Sonar id="6"  px="0.22"   py="-0.08"  rz="-0.5235"/>
  <xacro:Sonar id="7"  px="0.185"  py="-0.115" rz="-0.8725"/>
  <xacro:Sonar id="8"  px="0.145"  py="-0.13"  rz="-1.5705"/>
  <xacro:Sonar id="9"  px="-0.145" py="-0.13"  rz="-1.5705"/>
  <xacro:Sonar id="10" px="-0.185" py="-0.115" rz="-2.2685"/>
  <xacro:Sonar id="11" px="-0.22"  py="-0.08"  rz="-2.6175"/>
  <xacro:Sonar id="12" px="-0.24"  py="-0.025" rz="-2.9665"/>
  <xacro:Sonar id="13" px="-0.24"  py="0.025"  rz="2.9665"/>
  <xacro:Sonar id="14" px="-0.22"  py="0.08"   rz="2.6175"/>
  <xacro:Sonar id="15" px="-0.185" py="0.115"  rz="2.2685"/>
  <xacro:Sonar id="16" px="-0.145" py="0.13"   rz="1.5705"/>
-->
</robot>

