<sdf version='1.4'>
  <world name='default'>
    <model name='ground_plane'>
      <static>1</static>
      <link name='link'>
        <collision name='collision'>
          <geometry>
            <plane>
              <normal>0 0 1</normal>
              <size>100 100</size>
            </plane>
          </geometry>
          <surface>
            <friction>
              <ode>
                <mu>100</mu>
                <mu2>50</mu2>
              </ode>
            </friction>
            <bounce/>
            <contact>
              <ode/>
            </contact>
          </surface>
          <max_contacts>10</max_contacts>
        </collision>
        <visual name='visual'>
          <cast_shadows>0</cast_shadows>
          <geometry>
            <plane>
              <normal>0 0 1</normal>
              <size>100 100</size>
            </plane>
          </geometry>
          <material>
            <script>
              <uri>file://media/materials/scripts/gazebo.material</uri>
              <name>Gazebo/Grey</name>
            </script>
          </material>
        </visual>
        <velocity_decay>
          <linear>0</linear>
          <angular>0</angular>
        </velocity_decay>
        <self_collide>0</self_collide>
        <kinematic>0</kinematic>
        <gravity>1</gravity>
      </link>
    </model>
    <light name='sun' type='directional'>
      <cast_shadows>1</cast_shadows>
      <pose>0 0 10 0 -0 0</pose>
      <diffuse>0.8 0.8 0.8 1</diffuse>
      <specular>0.2 0.2 0.2 1</specular>
      <attenuation>
        <range>1000</range>
        <constant>0.9</constant>
        <linear>0.01</linear>
        <quadratic>0.001</quadratic>
      </attenuation>
      <direction>-0.5 0.1 -0.9</direction>
    </light>
    <gui fullscreen='0'>
      <camera name='user_camera'>
        <pose>11.6569 -6.08338 3.28853 0 0.275643 2.35619</pose>
        <view_controller>orbit</view_controller>
      </camera>
    </gui>
    <physics type='ode'>
      <max_step_size>0.001</max_step_size>
      <real_time_factor>1</real_time_factor>
      <real_time_update_rate>1000</real_time_update_rate>
      <gravity>0 0 -9.8</gravity>
    </physics>
    <scene>
      <ambient>0.4 0.4 0.4 1</ambient>
      <background>0.7 0.7 0.7 1</background>
      <shadows>1</shadows>
    </scene>
    <spherical_coordinates>
      <surface_model>EARTH_WGS84</surface_model>
      <latitude_deg>0</latitude_deg>
      <longitude_deg>0</longitude_deg>
      <elevation>0</elevation>
      <heading_deg>0</heading_deg>
    </spherical_coordinates>
    <model name='pioneer3at'>
      <link name='Pioneer3AT/base_link'>
        <pose>0 0 0 0 -0 0</pose>
        <inertial>
          <pose>0.0980052 0 0.262002 0 -0 0</pose>
          <mass>0.20001</mass>
          <inertia>
            <ixx>0.00202982</ixx>
            <ixy>0</ixy>
            <ixz>0.000227951</ixz>
            <iyy>0.00383493</iyy>
            <iyz>0</iyz>
            <izz>0.00380611</izz>
          </inertia>
        </inertial>
        <collision name='Pioneer3AT/base_link_collision'>
          <pose>0 0 0.177 0 -0 0</pose>
          <geometry>
            <box>
              <size>0.49 0.28 0.25</size>
            </box>
          </geometry>
          <surface>
            <contact>
              <ode/>
            </contact>
            <friction>
              <ode/>
            </friction>
            <bounce/>
          </surface>
          <max_contacts>10</max_contacts>
        </collision>
        <collision name='Pioneer3AT/base_link_collision_front_sonar'>
          <pose>0.193 0 0.25 0 -0 0</pose>
          <geometry>
            <mesh>
              <scale>1 1 1</scale>
              <uri>/home/guillaume/roscode/catkin_ws/src/pioneer3at/pioneer3at_description/meshes/front_sonar.stl</uri>
            </mesh>
          </geometry>
          <surface>
            <contact>
              <ode/>
            </contact>
            <friction>
              <ode/>
            </friction>
            <bounce/>
          </surface>
          <surface>
            <contact>
              <ode/>
            </contact>
            <friction>
              <ode/>
            </friction>
          </surface>
          <max_contacts>10</max_contacts>
        </collision>
        <collision name='Pioneer3AT/base_link_collision_hokuyo_link'>
          <pose>0.203 0 0.309 0 -0 0</pose>
          <geometry>
            <box>
              <size>0.1 0.1 0.1</size>
            </box>
          </geometry>
          <surface>
            <contact>
              <ode/>
            </contact>
            <friction>
              <ode/>
            </friction>
            <bounce/>
          </surface>
          <surface>
            <contact>
              <ode/>
            </contact>
            <friction>
              <ode/>
            </friction>
          </surface>
          <max_contacts>10</max_contacts>
        </collision>
        <collision name='Pioneer3AT/base_link_collision_top_plate'>
          <pose>0.003 0 0.274 0 -0 0</pose>
          <geometry>
            <mesh>
              <scale>1 1 1</scale>
              <uri>/home/guillaume/roscode/catkin_ws/src/pioneer3at/pioneer3at_description/meshes/top.stl</uri>
            </mesh>
          </geometry>
          <surface>
            <contact>
              <ode/>
            </contact>
            <friction>
              <ode/>
            </friction>
            <bounce/>
          </surface>
          <max_contacts>10</max_contacts>
        </collision>
        <visual name='Pioneer3AT/base_link_visual'>
          <pose>0 0 0.177 0 -0 0</pose>
          <geometry>
            <mesh>
              <scale>1 1 1</scale>
              <uri>/home/guillaume/roscode/catkin_ws/src/pioneer3at/pioneer3at_description/meshes/chassis.stl</uri>
            </mesh>
          </geometry>
          <material>
            <script>
              <name>Gazebo/Red</name>
              <uri>__default__</uri>
            </script>
          </material>
        </visual>
        <visual name='Pioneer3AT/base_link_visual_front_sonar'>
          <pose>0.193 0 0.25 0 -0 0</pose>
          <geometry>
            <mesh>
              <scale>1 1 1</scale>
              <uri>/home/guillaume/roscode/catkin_ws/src/pioneer3at/pioneer3at_description/meshes/front_sonar.stl</uri>
            </mesh>
          </geometry>
          <material>
            <script>
              <name>Gazebo/Yellow</name>
              <uri>__default__</uri>
            </script>
          </material>
        </visual>
        <visual name='Pioneer3AT/base_link_visual_hokuyo_link'>
          <pose>0.203 0 0.309 0 -0 0</pose>
          <geometry>
            <mesh>
              <scale>1 1 1</scale>
              <uri>/home/guillaume/roscode/catkin_ws/src/pioneer3at/pioneer3at_description/meshes/hokuyo.dae</uri>
            </mesh>
          </geometry>
        </visual>
        <visual name='Pioneer3AT/base_link_visual_rear_sonar'>
          <pose>-0.187 0 0.247 0 -0 0</pose>
          <geometry>
            <mesh>
              <scale>1 1 1</scale>
              <uri>/home/guillaume/roscode/catkin_ws/src/pioneer3at/pioneer3at_description/meshes/back_sonar.stl</uri>
            </mesh>
          </geometry>
          <material>
            <script>
              <name>Gazebo/Yellow</name>
              <uri>__default__</uri>
            </script>
          </material>
        </visual>
        <visual name='Pioneer3AT/base_link_visual_top_plate'>
          <pose>0.003 0 0.274 0 -0 0</pose>
          <geometry>
            <mesh>
              <scale>1 1 1</scale>
              <uri>/home/guillaume/roscode/catkin_ws/src/pioneer3at/pioneer3at_description/meshes/top.stl</uri>
            </mesh>
          </geometry>
          <material>
            <script>
              <name>Gazebo/Black</name>
              <uri>__default__</uri>
            </script>
          </material>
        </visual>
        <velocity_decay>
          <linear>0</linear>
          <angular>0</angular>
        </velocity_decay>
        <velocity_decay>
          <linear>0</linear>
          <angular>0</angular>
        </velocity_decay>
        <sensor name='head_hokuyo_sensor' type='gpu_ray'>
          <visualize>0</visualize>
          <update_rate>40</update_rate>
          <ray>
            <scan>
              <horizontal>
                <samples>720</samples>
                <resolution>1</resolution>
                <min_angle>-1.5708</min_angle>
                <max_angle>1.5708</max_angle>
              </horizontal>
            </scan>
            <range>
              <min>0.1</min>
              <max>30</max>
              <resolution>0.01</resolution>
            </range>
            <noise>
              <type>gaussian</type>
              <mean>0</mean>
              <stddev>0.01</stddev>
            </noise>
          </ray>
          <plugin name='gazebo_ros_head_hokuyo_controller' filename='libgazebo_ros_gpu_laser.so'>
            <topicName>/Pioneer3AT/laser/scan</topicName>
            <frameName>hokuyo_link</frameName>
            <robotNamespace>/</robotNamespace>
          </plugin>
          <pose>0.203 0 0.309 0 -0 0</pose>
        </sensor>
        <velocity_decay>
          <linear>0</linear>
          <angular>0</angular>
        </velocity_decay>
        <gravity>1</gravity>
        <velocity_decay>
          <linear>0</linear>
          <angular>0</angular>
        </velocity_decay>
        <self_collide>0</self_collide>
        <kinematic>0</kinematic>
      </link>
      <link name='front_left_axle'>
        <pose>0.135 0.156 0.111 0 -0 0</pose>
        <inertial>
          <pose>0.104167 0.205083 -0.05 0 -0 0</pose>
          <mass>1.2</mass>
          <inertia>
            <ixx>0.00986309</ixx>
            <ixy>-0.00461458</ixy>
            <ixz>0.00125</ixz>
            <iyy>0.00420617</iyy>
            <iyz>0.002215</iyz>
            <izz>0.0118673</izz>
          </inertia>
        </inertial>
        <collision name='front_left_axle_collision'>
          <pose>0 0 0 0 -0 0</pose>
          <geometry>
            <mesh>
              <scale>1 1 1</scale>
              <uri>/home/guillaume/roscode/catkin_ws/src/pioneer3at/pioneer3at_description/meshes/axle.stl</uri>
            </mesh>
          </geometry>
          <surface>
            <contact>
              <ode/>
            </contact>
            <friction>
              <ode/>
            </friction>
            <bounce/>
          </surface>
          <max_contacts>10</max_contacts>
        </collision>
        <collision name='front_left_axle_collision_front_left_hub'>
          <pose>0 0.041 0 0 -0 0</pose>
          <geometry>
            <mesh>
              <scale>1 1 1</scale>
              <uri>/home/guillaume/roscode/catkin_ws/src/pioneer3at/pioneer3at_description/meshes/hub.stl</uri>
            </mesh>
          </geometry>
          <surface>
            <contact>
              <ode/>
            </contact>
            <friction>
              <ode/>
            </friction>
            <bounce/>
          </surface>
          <surface>
            <contact>
              <ode/>
            </contact>
            <friction>
              <ode/>
            </friction>
          </surface>
          <max_contacts>10</max_contacts>
        </collision>
        <collision name='front_left_axle_collision_front_left_wheel'>
          <pose>0 0.041 0 0 -0 0</pose>
          <geometry>
            <mesh>
              <scale>1 1 1</scale>
              <uri>/home/guillaume/roscode/catkin_ws/src/pioneer3at/pioneer3at_description/meshes/wheel.stl</uri>
            </mesh>
          </geometry>
          <surface>
            <contact>
              <ode/>
            </contact>
            <friction>
              <ode/>
            </friction>
            <bounce/>
          </surface>
          <surface>
            <contact>
              <ode/>
            </contact>
            <friction>
              <ode/>
            </friction>
          </surface>
          <max_contacts>10</max_contacts>
        </collision>
        <visual name='front_left_axle_visual'>
          <pose>0 0 0 0 -0 0</pose>
          <geometry>
            <mesh>
              <scale>1 1 1</scale>
              <uri>/home/guillaume/roscode/catkin_ws/src/pioneer3at/pioneer3at_description/meshes/axle.stl</uri>
            </mesh>
          </geometry>
          <material>
            <script>
              <name>Gazebo/Grey</name>
              <uri>__default__</uri>
            </script>
          </material>
        </visual>
        <visual name='front_left_axle_visual_front_left_hub'>
          <pose>0 0.041 0 0 -0 0</pose>
          <geometry>
            <mesh>
              <scale>1 1 1</scale>
              <uri>/home/guillaume/roscode/catkin_ws/src/pioneer3at/pioneer3at_description/meshes/hub.stl</uri>
            </mesh>
          </geometry>
          <material>
            <script>
              <name>Gazebo/Yellow</name>
              <uri>__default__</uri>
            </script>
          </material>
        </visual>
        <visual name='front_left_axle_visual_front_left_wheel'>
          <pose>0 0.041 0 0 -0 0</pose>
          <geometry>
            <mesh>
              <scale>1 1 1</scale>
              <uri>/home/guillaume/roscode/catkin_ws/src/pioneer3at/pioneer3at_description/meshes/wheel.stl</uri>
            </mesh>
          </geometry>
          <material>
            <script>
              <name>Gazebo/Black</name>
              <uri>__default__</uri>
            </script>
          </material>
        </visual>
        <velocity_decay>
          <linear>0</linear>
          <angular>0</angular>
        </velocity_decay>
        <velocity_decay>
          <linear>0</linear>
          <angular>0</angular>
        </velocity_decay>
        <gravity>1</gravity>
        <velocity_decay>
          <linear>0</linear>
          <angular>0</angular>
        </velocity_decay>
        <self_collide>0</self_collide>
        <kinematic>0</kinematic>
      </link>
      <joint name='front_left_axle_joint' type='revolute'>
        <child>front_left_axle</child>
        <parent>Pioneer3AT/base_link</parent>
        <axis>
          <xyz>0 1 0</xyz>
          <limit>
            <lower>-1e+16</lower>
            <upper>1e+16</upper>
          </limit>
          <dynamics/>
        </axis>
      </joint>
      <link name='front_right_axle'>
        <pose>0.135 -0.156 0.111 0 -0 0</pose>
        <inertial>
          <pose>0.104167 -0.205083 -0.05 0 -0 0</pose>
          <mass>1.2</mass>
          <inertia>
            <ixx>0.00986309</ixx>
            <ixy>0.00461458</ixy>
            <ixz>0.00125</ixz>
            <iyy>0.00420617</iyy>
            <iyz>-0.002215</iyz>
            <izz>0.0118673</izz>
          </inertia>
        </inertial>
        <collision name='front_right_axle_collision'>
          <pose>0 0 0 0 -0 0</pose>
          <geometry>
            <mesh>
              <scale>1 1 1</scale>
              <uri>/home/guillaume/roscode/catkin_ws/src/pioneer3at/pioneer3at_description/meshes/axle.stl</uri>
            </mesh>
          </geometry>
          <surface>
            <contact>
              <ode/>
            </contact>
            <friction>
              <ode/>
            </friction>
            <bounce/>
          </surface>
          <max_contacts>10</max_contacts>
        </collision>
        <collision name='front_right_axle_collision_front_right_hub'>
          <pose>0 -0.041 0 0 -0 0</pose>
          <geometry>
            <mesh>
              <scale>1 1 1</scale>
              <uri>/home/guillaume/roscode/catkin_ws/src/pioneer3at/pioneer3at_description/meshes/hub.stl</uri>
            </mesh>
          </geometry>
          <surface>
            <contact>
              <ode/>
            </contact>
            <friction>
              <ode/>
            </friction>
            <bounce/>
          </surface>
          <surface>
            <contact>
              <ode/>
            </contact>
            <friction>
              <ode/>
            </friction>
          </surface>
          <max_contacts>10</max_contacts>
        </collision>
        <collision name='front_right_axle_collision_front_right_wheel'>
          <pose>0 -0.041 0 0 -0 0</pose>
          <geometry>
            <mesh>
              <scale>1 1 1</scale>
              <uri>/home/guillaume/roscode/catkin_ws/src/pioneer3at/pioneer3at_description/meshes/wheel.stl</uri>
            </mesh>
          </geometry>
          <surface>
            <contact>
              <ode/>
            </contact>
            <friction>
              <ode/>
            </friction>
            <bounce/>
          </surface>
          <surface>
            <contact>
              <ode/>
            </contact>
            <friction>
              <ode/>
            </friction>
          </surface>
          <max_contacts>10</max_contacts>
        </collision>
        <visual name='front_right_axle_visual'>
          <pose>0 0 0 0 -0 0</pose>
          <geometry>
            <mesh>
              <scale>1 1 1</scale>
              <uri>/home/guillaume/roscode/catkin_ws/src/pioneer3at/pioneer3at_description/meshes/axle.stl</uri>
            </mesh>
          </geometry>
          <material>
            <script>
              <name>Gazebo/Grey</name>
              <uri>__default__</uri>
            </script>
          </material>
        </visual>
        <visual name='front_right_axle_visual_front_right_hub'>
          <pose>0 -0.041 0 -3.14 0 0</pose>
          <geometry>
            <mesh>
              <scale>1 1 1</scale>
              <uri>/home/guillaume/roscode/catkin_ws/src/pioneer3at/pioneer3at_description/meshes/hub.stl</uri>
            </mesh>
          </geometry>
          <material>
            <script>
              <name>Gazebo/Yellow</name>
              <uri>__default__</uri>
            </script>
          </material>
        </visual>
        <visual name='front_right_axle_visual_front_right_wheel'>
          <pose>0 -0.041 0 0 -0 0</pose>
          <geometry>
            <mesh>
              <scale>1 1 1</scale>
              <uri>/home/guillaume/roscode/catkin_ws/src/pioneer3at/pioneer3at_description/meshes/wheel.stl</uri>
            </mesh>
          </geometry>
          <material>
            <script>
              <name>Gazebo/Black</name>
              <uri>__default__</uri>
            </script>
          </material>
        </visual>
        <velocity_decay>
          <linear>0</linear>
          <angular>0</angular>
        </velocity_decay>
        <velocity_decay>
          <linear>0</linear>
          <angular>0</angular>
        </velocity_decay>
        <gravity>1</gravity>
        <velocity_decay>
          <linear>0</linear>
          <angular>0</angular>
        </velocity_decay>
        <self_collide>0</self_collide>
        <kinematic>0</kinematic>
      </link>
      <joint name='front_right_axle_joint' type='revolute'>
        <child>front_right_axle</child>
        <parent>Pioneer3AT/base_link</parent>
        <axis>
          <xyz>0 1 0</xyz>
          <limit>
            <lower>-1e+16</lower>
            <upper>1e+16</upper>
          </limit>
          <dynamics/>
        </axis>
      </joint>
      <link name='rear_left_axle'>
        <pose>-0.135 0.156 0.111 0 -0 0</pose>
        <inertial>
          <pose>-0.104167 0.205083 -0.05 0 -0 0</pose>
          <mass>1.2</mass>
          <inertia>
            <ixx>0.00986309</ixx>
            <ixy>0.00461458</ixy>
            <ixz>-0.00125</ixz>
            <iyy>0.00420617</iyy>
            <iyz>0.002215</iyz>
            <izz>0.0118673</izz>
          </inertia>
        </inertial>
        <collision name='rear_left_axle_collision'>
          <pose>0 0 0 0 -0 0</pose>
          <geometry>
            <mesh>
              <scale>1 1 1</scale>
              <uri>/home/guillaume/roscode/catkin_ws/src/pioneer3at/pioneer3at_description/meshes/axle.stl</uri>
            </mesh>
          </geometry>
          <surface>
            <contact>
              <ode/>
            </contact>
            <friction>
              <ode/>
            </friction>
            <bounce/>
          </surface>
          <max_contacts>10</max_contacts>
        </collision>
        <collision name='rear_left_axle_collision_rear_left_hub'>
          <pose>0 0.041 0 0 -0 0</pose>
          <geometry>
            <mesh>
              <scale>1 1 1</scale>
              <uri>/home/guillaume/roscode/catkin_ws/src/pioneer3at/pioneer3at_description/meshes/hub.stl</uri>
            </mesh>
          </geometry>
          <surface>
            <contact>
              <ode/>
            </contact>
            <friction>
              <ode/>
            </friction>
            <bounce/>
          </surface>
          <surface>
            <contact>
              <ode/>
            </contact>
            <friction>
              <ode/>
            </friction>
          </surface>
          <max_contacts>10</max_contacts>
        </collision>
        <collision name='rear_left_axle_collision_rear_left_wheel'>
          <pose>0 0.041 0 0 -0 0</pose>
          <geometry>
            <mesh>
              <scale>1 1 1</scale>
              <uri>/home/guillaume/roscode/catkin_ws/src/pioneer3at/pioneer3at_description/meshes/wheel.stl</uri>
            </mesh>
          </geometry>
          <surface>
            <contact>
              <ode/>
            </contact>
            <friction>
              <ode/>
            </friction>
            <bounce/>
          </surface>
          <surface>
            <contact>
              <ode/>
            </contact>
            <friction>
              <ode/>
            </friction>
          </surface>
          <max_contacts>10</max_contacts>
        </collision>
        <visual name='rear_left_axle_visual'>
          <pose>0 0 0 0 -0 0</pose>
          <geometry>
            <mesh>
              <scale>1 1 1</scale>
              <uri>/home/guillaume/roscode/catkin_ws/src/pioneer3at/pioneer3at_description/meshes/axle.stl</uri>
            </mesh>
          </geometry>
          <material>
            <script>
              <name>Gazebo/Grey</name>
              <uri>__default__</uri>
            </script>
          </material>
        </visual>
        <visual name='rear_left_axle_visual_rear_left_hub'>
          <pose>0 0.041 0 0 -0 0</pose>
          <geometry>
            <mesh>
              <scale>1 1 1</scale>
              <uri>/home/guillaume/roscode/catkin_ws/src/pioneer3at/pioneer3at_description/meshes/hub.stl</uri>
            </mesh>
          </geometry>
          <material>
            <script>
              <name>Gazebo/Yellow</name>
              <uri>__default__</uri>
            </script>
          </material>
        </visual>
        <visual name='rear_left_axle_visual_rear_left_wheel'>
          <pose>0 0.041 0 0 -0 0</pose>
          <geometry>
            <mesh>
              <scale>1 1 1</scale>
              <uri>/home/guillaume/roscode/catkin_ws/src/pioneer3at/pioneer3at_description/meshes/wheel.stl</uri>
            </mesh>
          </geometry>
          <material>
            <script>
              <name>Gazebo/Black</name>
              <uri>__default__</uri>
            </script>
          </material>
        </visual>
        <velocity_decay>
          <linear>0</linear>
          <angular>0</angular>
        </velocity_decay>
        <velocity_decay>
          <linear>0</linear>
          <angular>0</angular>
        </velocity_decay>
        <gravity>1</gravity>
        <velocity_decay>
          <linear>0</linear>
          <angular>0</angular>
        </velocity_decay>
        <self_collide>0</self_collide>
        <kinematic>0</kinematic>
      </link>
      <joint name='rear_left_axle_joint' type='revolute'>
        <child>rear_left_axle</child>
        <parent>Pioneer3AT/base_link</parent>
        <axis>
          <xyz>0 1 0</xyz>
          <limit>
            <lower>-1e+16</lower>
            <upper>1e+16</upper>
          </limit>
          <dynamics/>
        </axis>
      </joint>
      <link name='rear_right_axle'>
        <pose>-0.135 -0.156 0.111 0 -0 0</pose>
        <inertial>
          <pose>-0.104167 -0.205083 -0.05 0 -0 0</pose>
          <mass>1.2</mass>
          <inertia>
            <ixx>0.00986309</ixx>
            <ixy>-0.00461458</ixy>
            <ixz>-0.00125</ixz>
            <iyy>0.00420617</iyy>
            <iyz>-0.002215</iyz>
            <izz>0.0118673</izz>
          </inertia>
        </inertial>
        <collision name='rear_right_axle_collision'>
          <pose>0 0 0 0 -0 0</pose>
          <geometry>
            <mesh>
              <scale>1 1 1</scale>
              <uri>/home/guillaume/roscode/catkin_ws/src/pioneer3at/pioneer3at_description/meshes/axle.stl</uri>
            </mesh>
          </geometry>
          <surface>
            <contact>
              <ode/>
            </contact>
            <friction>
              <ode/>
            </friction>
            <bounce/>
          </surface>
          <max_contacts>10</max_contacts>
        </collision>
        <collision name='rear_right_axle_collision_rear_right_hub'>
          <pose>0 -0.041 0 0 -0 0</pose>
          <geometry>
            <mesh>
              <scale>1 1 1</scale>
              <uri>/home/guillaume/roscode/catkin_ws/src/pioneer3at/pioneer3at_description/meshes/hub.stl</uri>
            </mesh>
          </geometry>
          <surface>
            <contact>
              <ode/>
            </contact>
            <friction>
              <ode/>
            </friction>
            <bounce/>
          </surface>
          <surface>
            <contact>
              <ode/>
            </contact>
            <friction>
              <ode/>
            </friction>
          </surface>
          <max_contacts>10</max_contacts>
        </collision>
        <collision name='rear_right_axle_collision_rear_right_wheel'>
          <pose>0 -0.041 0 0 -0 0</pose>
          <geometry>
            <mesh>
              <scale>1 1 1</scale>
              <uri>/home/guillaume/roscode/catkin_ws/src/pioneer3at/pioneer3at_description/meshes/wheel.stl</uri>
            </mesh>
          </geometry>
          <surface>
            <contact>
              <ode/>
            </contact>
            <friction>
              <ode/>
            </friction>
            <bounce/>
          </surface>
          <surface>
            <contact>
              <ode/>
            </contact>
            <friction>
              <ode/>
            </friction>
          </surface>
          <max_contacts>10</max_contacts>
        </collision>
        <visual name='rear_right_axle_visual'>
          <pose>0 0 0 0 -0 0</pose>
          <geometry>
            <mesh>
              <scale>1 1 1</scale>
              <uri>/home/guillaume/roscode/catkin_ws/src/pioneer3at/pioneer3at_description/meshes/axle.stl</uri>
            </mesh>
          </geometry>
          <material>
            <script>
              <name>Gazebo/Grey</name>
              <uri>__default__</uri>
            </script>
          </material>
        </visual>
        <visual name='rear_right_axle_visual_rear_right_hub'>
          <pose>0 -0.041 0 -3.14 0 0</pose>
          <geometry>
            <mesh>
              <scale>1 1 1</scale>
              <uri>/home/guillaume/roscode/catkin_ws/src/pioneer3at/pioneer3at_description/meshes/hub.stl</uri>
            </mesh>
          </geometry>
          <material>
            <script>
              <name>Gazebo/Yellow</name>
              <uri>__default__</uri>
            </script>
          </material>
        </visual>
        <visual name='rear_right_axle_visual_rear_right_wheel'>
          <pose>0 -0.041 0 0 -0 0</pose>
          <geometry>
            <mesh>
              <scale>1 1 1</scale>
              <uri>/home/guillaume/roscode/catkin_ws/src/pioneer3at/pioneer3at_description/meshes/wheel.stl</uri>
            </mesh>
          </geometry>
          <material>
            <script>
              <name>Gazebo/Black</name>
              <uri>__default__</uri>
            </script>
          </material>
        </visual>
        <velocity_decay>
          <linear>0</linear>
          <angular>0</angular>
        </velocity_decay>
        <velocity_decay>
          <linear>0</linear>
          <angular>0</angular>
        </velocity_decay>
        <gravity>1</gravity>
        <velocity_decay>
          <linear>0</linear>
          <angular>0</angular>
        </velocity_decay>
        <self_collide>0</self_collide>
        <kinematic>0</kinematic>
      </link>
      <joint name='rear_right_axle_joint' type='revolute'>
        <child>rear_right_axle</child>
        <parent>Pioneer3AT/base_link</parent>
        <axis>
          <xyz>0 1 0</xyz>
          <limit>
            <lower>-1e+16</lower>
            <upper>1e+16</upper>
          </limit>
          <dynamics/>
        </axis>
      </joint>
      <pose>0 0 0 0 -0 0</pose>
      <static>0</static>
    </model>
    <model name='grey_wall'>
      <static>1</static>
      <link name='link'>
        <pose>0 0 1.4 0 -0 0</pose>
        <collision name='collision'>
          <geometry>
            <box>
              <size>7.5 0.2 2.8</size>
            </box>
          </geometry>
          <max_contacts>10</max_contacts>
          <surface>
            <bounce/>
            <friction>
              <ode/>
            </friction>
            <contact>
              <ode/>
            </contact>
          </surface>
        </collision>
        <visual name='visual'>
          <cast_shadows>0</cast_shadows>
          <geometry>
            <box>
              <size>7.5 0.2 2.8</size>
            </box>
          </geometry>
          <material>
            <script>
              <uri>model://grey_wall/materials/scripts</uri>
              <uri>model://grey_wall/materials/textures</uri>
              <name>vrc/grey_wall</name>
            </script>
          </material>
        </visual>
        <velocity_decay>
          <linear>0</linear>
          <angular>0</angular>
        </velocity_decay>
        <self_collide>0</self_collide>
        <kinematic>0</kinematic>
        <gravity>1</gravity>
      </link>
      <pose>1 1 0 0 -0 0</pose>
    </model>
    <state world_name='default'>
      <sim_time>36 581000000</sim_time>
      <real_time>36 883174832</real_time>
      <wall_time>1415197267 768720717</wall_time>
      <model name='grey_wall'>
        <pose>1 1 0 0 -0 0</pose>
        <link name='link'>
          <pose>1 1 1.4 0 -0 0</pose>
          <velocity>0 0 0 0 -0 0</velocity>
          <acceleration>0 0 0 0 -0 0</acceleration>
          <wrench>0 0 0 0 -0 0</wrench>
        </link>
      </model>
      <model name='ground_plane'>
        <pose>0 0 0 0 -0 0</pose>
        <link name='link'>
          <pose>0 0 0 0 -0 0</pose>
          <velocity>0 0 0 0 -0 0</velocity>
          <acceleration>0 0 0 0 -0 0</acceleration>
          <wrench>0 0 0 0 -0 0</wrench>
        </link>
      </model>
      <model name='pioneer3at'>
        <pose>-0.029288 -0.006464 0.000494 1.1e-05 0.002763 0.007705</pose>
        <link name='Pioneer3AT/base_link'>
          <pose>-0.029288 -0.006464 0.000494 1.1e-05 0.002763 0.007705</pose>
          <velocity>-0.001406 -0.001032 0.000703 0.00362 0.003176 0.00389</velocity>
          <acceleration>0 0 0 0 -0 0</acceleration>
          <wrench>0 0 0 0 -0 0</wrench>
        </link>
        <link name='front_left_axle'>
          <pose>0.104812 0.150578 0.111129 2.3e-05 0.943355 0.007726</pose>
          <velocity>-0.001664 -0.00048 0.001853 0.003714 -0.017353 0.003915</velocity>
          <acceleration>0 0 0 0 -0 0</acceleration>
          <wrench>0 0 0 0 -0 0</wrench>
        </link>
        <link name='front_right_axle'>
          <pose>0.107217 -0.161417 0.111115 7e-05 0.942491 0.007762</pose>
          <velocity>-0.000629 -0.001423 -0.000421 0.006532 0.008046 0.002059</velocity>
          <acceleration>0 0 0 0 -0 0</acceleration>
          <wrench>0 0 0 0 -0 0</wrench>
        </link>
        <link name='rear_left_axle'>
          <pose>-0.165177 0.148498 0.111875 4.8e-05 -1.20493 0.007658</pose>
          <velocity>-0.001316 -0.000289 0.003279 0.002257 -0.013734 0.003261</velocity>
          <acceleration>0 0 0 0 -0 0</acceleration>
          <wrench>0 0 0 0 -0 0</wrench>
        </link>
        <link name='rear_right_axle'>
          <pose>-0.162774 -0.1635 0.111859 9.4e-05 -1.20631 0.00762</pose>
          <velocity>-0.000522 -0.001457 -5e-05 0.009558 0.004347 0.002529</velocity>
          <acceleration>0 0 0 0 -0 0</acceleration>
          <wrench>0 0 0 0 -0 0</wrench>
        </link>
      </model>
    </state>
  </world>
</sdf>
